Traceback (most recent call last):
  File "/usr/local/lib/python3.9/site-packages/jupyter_cache/executors/utils.py", line 51, in single_nb_execution
    executenb(
  File "/usr/local/lib/python3.9/site-packages/nbclient/client.py", line 1093, in execute
    return NotebookClient(nb=nb, resources=resources, km=km, **kwargs).execute()
  File "/usr/local/lib/python3.9/site-packages/nbclient/util.py", line 84, in wrapped
    return just_run(coro(*args, **kwargs))
  File "/usr/local/lib/python3.9/site-packages/nbclient/util.py", line 62, in just_run
    return loop.run_until_complete(coro)
  File "/usr/local/Cellar/python@3.9/3.9.13/Frameworks/Python.framework/Versions/3.9/lib/python3.9/asyncio/base_events.py", line 647, in run_until_complete
    return future.result()
  File "/usr/local/lib/python3.9/site-packages/nbclient/client.py", line 559, in async_execute
    await self.async_execute_cell(
  File "/usr/local/lib/python3.9/site-packages/nbclient/client.py", line 854, in async_execute_cell
    self._check_raise_for_error(cell, exec_reply)
  File "/usr/local/lib/python3.9/site-packages/nbclient/client.py", line 756, in _check_raise_for_error
    raise CellExecutionError.from_cell_and_msg(cell, exec_reply_content)
nbclient.exceptions.CellExecutionError: An error occurred while executing the following cell:
------------------
x_1 = linsolve([A,b_1])
x_1.evalf(4)
------------------

[0;31m---------------------------------------------------------------------------[0m
[0;31mKeyError[0m                                  Traceback (most recent call last)
File [0;32m/usr/local/lib/python3.9/site-packages/sympy/core/evalf.py:1365[0m, in [0;36mevalf[0;34m(x, prec, options)[0m
[1;32m   1364[0m [38;5;28;01mtry[39;00m:
[0;32m-> 1365[0m     rf [38;5;241m=[39m [43mevalf_table[49m[43m[[49m[43mx[49m[38;5;241;43m.[39;49m[43mfunc[49m[43m][49m
[1;32m   1366[0m     r [38;5;241m=[39m rf(x, prec, options)

[0;31mKeyError[0m: <class 'sympy.sets.sets.FiniteSet'>

During handling of the above exception, another exception occurred:

[0;31mAttributeError[0m                            Traceback (most recent call last)
Input [0;32mIn [2][0m, in [0;36m<module>[0;34m[0m
[1;32m      1[0m x_1 [38;5;241m=[39m linsolve([A,b_1])
[0;32m----> 2[0m [43mx_1[49m[38;5;241;43m.[39;49m[43mevalf[49m[43m([49m[38;5;241;43m4[39;49m[43m)[49m

File [0;32m/usr/local/lib/python3.9/site-packages/sympy/core/evalf.py:1514[0m, in [0;36mEvalfMixin.evalf[0;34m(self, n, subs, maxn, chop, strict, quad, verbose)[0m
[1;32m   1512[0m     options[[38;5;124m'[39m[38;5;124mquad[39m[38;5;124m'[39m] [38;5;241m=[39m quad
[1;32m   1513[0m [38;5;28;01mtry[39;00m:
[0;32m-> 1514[0m     result [38;5;241m=[39m [43mevalf[49m[43m([49m[38;5;28;43mself[39;49m[43m,[49m[43m [49m[43mprec[49m[43m [49m[38;5;241;43m+[39;49m[43m [49m[38;5;241;43m4[39;49m[43m,[49m[43m [49m[43moptions[49m[43m)[49m
[1;32m   1515[0m [38;5;28;01mexcept[39;00m [38;5;167;01mNotImplementedError[39;00m:
[1;32m   1516[0m     [38;5;66;03m# Fall back to the ordinary evalf[39;00m
[1;32m   1517[0m     [38;5;28;01mif[39;00m [38;5;28mhasattr[39m([38;5;28mself[39m, [38;5;124m'[39m[38;5;124msubs[39m[38;5;124m'[39m) [38;5;129;01mand[39;00m subs [38;5;129;01mis[39;00m [38;5;129;01mnot[39;00m [38;5;28;01mNone[39;00m:  [38;5;66;03m# issue 20291[39;00m

File [0;32m/usr/local/lib/python3.9/site-packages/sympy/core/evalf.py:1371[0m, in [0;36mevalf[0;34m(x, prec, options)[0m
[1;32m   1369[0m [38;5;28;01mif[39;00m [38;5;124m'[39m[38;5;124msubs[39m[38;5;124m'[39m [38;5;129;01min[39;00m options:
[1;32m   1370[0m     x [38;5;241m=[39m x[38;5;241m.[39msubs(evalf_subs(prec, options[[38;5;124m'[39m[38;5;124msubs[39m[38;5;124m'[39m]))
[0;32m-> 1371[0m xe [38;5;241m=[39m [43mx[49m[38;5;241;43m.[39;49m[43m_eval_evalf[49m[43m([49m[43mprec[49m[43m)[49m
[1;32m   1372[0m [38;5;28;01mif[39;00m xe [38;5;129;01mis[39;00m [38;5;28;01mNone[39;00m:
[1;32m   1373[0m     [38;5;28;01mraise[39;00m [38;5;167;01mNotImplementedError[39;00m

File [0;32m/usr/local/lib/python3.9/site-packages/sympy/sets/sets.py:1904[0m, in [0;36mFiniteSet._eval_evalf[0;34m(self, prec)[0m
[1;32m   1903[0m [38;5;28;01mdef[39;00m [38;5;21m_eval_evalf[39m([38;5;28mself[39m, prec):
[0;32m-> 1904[0m     [38;5;28;01mreturn[39;00m FiniteSet([38;5;241m*[39m[elem[38;5;241m.[39mevalf(n[38;5;241m=[39mprec_to_dps(prec)) [38;5;28;01mfor[39;00m elem [38;5;129;01min[39;00m [38;5;28mself[39m])

File [0;32m/usr/local/lib/python3.9/site-packages/sympy/sets/sets.py:1904[0m, in [0;36m<listcomp>[0;34m(.0)[0m
[1;32m   1903[0m [38;5;28;01mdef[39;00m [38;5;21m_eval_evalf[39m([38;5;28mself[39m, prec):
[0;32m-> 1904[0m     [38;5;28;01mreturn[39;00m FiniteSet([38;5;241m*[39m[[43melem[49m[38;5;241;43m.[39;49m[43mevalf[49m(n[38;5;241m=[39mprec_to_dps(prec)) [38;5;28;01mfor[39;00m elem [38;5;129;01min[39;00m [38;5;28mself[39m])

[0;31mAttributeError[0m: 'Tuple' object has no attribute 'evalf'
AttributeError: 'Tuple' object has no attribute 'evalf'

